<?xml version='1.0'?>
<sdf version='1.6'>
  <model name='my_robot'>
    <link name='chassis'>
      <pose frame=''>0 0 0.2 0 -0 0</pose>
      <inertial>
        <mass>15</mass>
        <pose frame=''>0 0 0.1 0 -0 0</pose>
        <inertia>
          <ixx>0.35595</ixx>
          <iyy>1.525</iyy>
          <izz>0.1125</izz>
        </inertia>
      </inertial>
      <self_collide>0</self_collide>
      <kinematic>0</kinematic>
      <sensor name='ir4' type='ray'>
        <pose frame=''> 0.049 -0.152  0 0 -0 -1.2566370614</pose>
        <ray>
          <scan>
            <horizontal>
              <samples>1</samples>
              <resolution>1</resolution>
              <min_angle>-0.0001</min_angle>
              <max_angle>0.0001</max_angle>
            </horizontal>
            <vertical>
              <samples>1</samples>
              <min_angle>0</min_angle>
              <max_angle>0</max_angle>
            </vertical>
          </scan>
          <range>
            <min>0.08</min>
            <max>0.8</max>
            <resolution>0.01</resolution>
          </range>
          <noise>
            <type>gaussian</type>
            <mean>0</mean>
            <stddev>0.01</stddev>
          </noise>
        </ray>
        <plugin name='gazebo_ros_head_hokuyo_controller' filename='libgazebo_ros_laser.so'>
          <topicName>/ir</topicName>
          <frameName>ir4</frameName>
        </plugin>
        <always_on>1</always_on>
        <update_rate>10</update_rate>
        <visualize>1</visualize>
      </sensor>
      <sensor name='ir3' type='ray'>
        <pose frame=''> -0.1294427191 -0.09404564037 0 0 -0 -2.5132741229</pose>
        <ray>
          <scan>
            <horizontal>
              <samples>1</samples>
              <resolution>1</resolution>
              <min_angle>-0.0001</min_angle>
              <max_angle>0.0001</max_angle>
            </horizontal>
            <vertical>
              <samples>1</samples>
              <min_angle>0</min_angle>
              <max_angle>0</max_angle>
            </vertical>
          </scan>
          <range>
            <min>0.08</min>
            <max>0.8</max>
            <resolution>0.01</resolution>
          </range>
          <noise>
            <type>gaussian</type>
            <mean>0</mean>
            <stddev>0.01</stddev>
          </noise>
        </ray>
        <plugin name='gazebo_ros_head_hokuyo_controller' filename='libgazebo_ros_laser.so'>
          <topicName>/ir</topicName>
          <frameName>ir3</frameName>
        </plugin>
        <always_on>1</always_on>
        <update_rate>10</update_rate>
        <visualize>1</visualize>
      </sensor>
       <sensor name='ir2' type='ray'>
        <pose frame=''> -0.1294427191 0.09404564037 0 0 -0 2.5132741229</pose>
        <ray>
          <scan>
            <horizontal>
              <samples>1</samples>
              <resolution>1</resolution>
              <min_angle>-0.0001</min_angle>
              <max_angle>0.0001</max_angle>
            </horizontal>
            <vertical>
              <samples>1</samples>
              <min_angle>0</min_angle>
              <max_angle>0</max_angle>
            </vertical>
          </scan>
          <range>
            <min>0.08</min>
            <max>0.8</max>
            <resolution>0.01</resolution>
          </range>
          <noise>
            <type>gaussian</type>
            <mean>0</mean>
            <stddev>0.01</stddev>
          </noise>
        </ray>
        <plugin name='gazebo_ros_head_hokuyo_controller' filename='libgazebo_ros_laser.so'>
          <topicName>/ir</topicName>
          <frameName>ir2</frameName>
        </plugin>
        <always_on>1</always_on>
        <update_rate>10</update_rate>
        <visualize>1</visualize>
      </sensor>
      <sensor name='ir1' type='ray'>
        <pose frame=''>0.049 0.152  0 0 -0 1.2566370614</pose>
        <ray>
          <scan>
            <horizontal>
              <samples>1</samples>
              <resolution>1</resolution>
              <min_angle>-0.0001</min_angle>
              <max_angle>0.0001</max_angle>
            </horizontal>
            <vertical>
              <samples>1</samples>
              <min_angle>0</min_angle>
              <max_angle>0</max_angle>
            </vertical>
          </scan>
          <range>
            <min>0.08</min>
            <max>0.8</max>
            <resolution>0.01</resolution>
          </range>
          <noise>
            <type>gaussian</type>
            <mean>0</mean>
            <stddev>0.01</stddev>
          </noise>
        </ray>
        <plugin name='gazebo_ros_head_hokuyo_controller' filename='libgazebo_ros_laser.so'>
          <topicName>/ir</topicName>
          <frameName>ir1</frameName>
        </plugin>
        <always_on>1</always_on>
        <update_rate>10</update_rate>
        <visualize>1</visualize>
      </sensor>
      <sensor name='ir0' type='ray'>
        <pose frame=''>0.17 0 0 0 -0 0</pose>
        <ray>
          <scan>
            <horizontal>
              <samples>1</samples>
              <resolution>1</resolution>
              <min_angle>-0.0001</min_angle>
              <max_angle>0.0001</max_angle>
            </horizontal>
            <vertical>
              <samples>1</samples>
              <min_angle>0</min_angle>
              <max_angle>0</max_angle>
            </vertical>
          </scan>
          <range>
            <min>0.08</min>
            <max>0.8</max>
            <resolution>0.01</resolution>
          </range>
          <noise>
            <type>gaussian</type>
            <mean>0</mean>
            <stddev>0.01</stddev>
          </noise>
        </ray>
        <plugin name='gazebo_ros_head_hokuyo_controller' filename='libgazebo_ros_laser.so'>
          <topicName>/ir</topicName>
          <frameName>ir0</frameName>
        </plugin>
        <always_on>1</always_on>
        <update_rate>10</update_rate>
        <visualize>1</visualize>
      </sensor>
      <visual name='visual'>
        <geometry>
          <cylinder>
            <radius>0.15</radius>
            <length>0.3</length>
          </cylinder>
        </geometry>
        <pose frame=''>0 0 0 0 -0 0</pose>
        <cast_shadows>1</cast_shadows>
        <transparency>0</transparency>
      </visual>
      <visual name='caster_visual'>
        <pose frame=''>-0.12 0 -0.15 0 -0 0</pose>
        <geometry>
          <sphere>
            <radius>0.05</radius>
          </sphere>
        </geometry>
        <cast_shadows>1</cast_shadows>
        <transparency>0</transparency>
      </visual>
      <collision name='collision'>
        <laser_retro>0</laser_retro>
        <max_contacts>10</max_contacts>
        <pose frame=''>0 0 0 0 -0 0</pose>
        <geometry>
          <cylinder>
            <radius>0.15</radius>
            <length>0.3</length>
          </cylinder>
        </geometry>
      </collision>
      <collision name='caster_collision'>
        <laser_retro>0</laser_retro>
        <max_contacts>10</max_contacts>
        <pose frame=''>-0.12 0 -0.15 0 -0 0</pose>
        <geometry>
          <sphere>
            <radius>0.05</radius>
          </sphere>
        </geometry>
        <surface>
          <friction>
            <ode>
              <mu>0</mu>
              <mu2>0</mu2>
              <fdir1>0 0 0</fdir1>
              <slip1>1</slip1>
              <slip2>1</slip2>
            </ode>
            <torsional>
              <coefficient>1</coefficient>
              <patch_radius>0</patch_radius>
              <surface_radius>0</surface_radius>
              <use_patch_radius>1</use_patch_radius>
              <ode>
                <slip>0</slip>
              </ode>
            </torsional>
          </friction>
          <bounce>
            <restitution_coefficient>0</restitution_coefficient>
            <threshold>1e+06</threshold>
          </bounce>
          <contact>
            <collide_without_contact>0</collide_without_contact>
            <collide_without_contact_bitmask>1</collide_without_contact_bitmask>
            <collide_bitmask>1</collide_bitmask>
            <ode>
              <soft_cfm>0</soft_cfm>
              <soft_erp>0.2</soft_erp>
              <kp>1e+13</kp>
              <kd>1</kd>
              <max_vel>0.01</max_vel>
              <min_depth>0</min_depth>
            </ode>
            <bullet>
              <split_impulse>1</split_impulse>
              <split_impulse_penetration_threshold>-0.01</split_impulse_penetration_threshold>
              <soft_cfm>0</soft_cfm>
              <soft_erp>0.2</soft_erp>
              <kp>1e+13</kp>
              <kd>1</kd>
            </bullet>
          </contact>
        </surface>
      </collision>
    </link>
    <link name='left_wheel'>
      <pose frame=''>0.1 0.17 0.065 0.000558 1.5707 1.57126</pose>
      <inertial>
        <inertia>
          <ixx>1</ixx>
          <ixy>0</ixy>
          <ixz>0</ixz>
          <iyy>1</iyy>
          <iyz>0</iyz>
          <izz>1</izz>
        </inertia>
        <mass>1</mass>
      </inertial>
      <self_collide>0</self_collide>
      <kinematic>0</kinematic>
      <visual name='visual'>
        <geometry>
          <cylinder>
            <radius>0.065</radius>
            <length>0.02</length>
          </cylinder>
        </geometry>
        <pose frame=''>0 0 0 0 -0 0</pose>
      </visual>
      <collision name='collision'>
        <pose frame=''>0 0 0 0 -0 0</pose>
        <geometry>
          <cylinder>
            <radius>0.065</radius>
            <length>0.02</length>
          </cylinder>
        </geometry>
      </collision>
    </link>
    <link name='right_wheel'>
      <pose frame=''>0.1 -0.17 0.065 0.000558 1.5707 1.57126</pose>
      <inertial>
        <inertia>
          <ixx>1</ixx>
          <ixy>0</ixy>
          <ixz>0</ixz>
          <iyy>1</iyy>
          <iyz>0</iyz>
          <izz>1</izz>
        </inertia>
        <mass>1</mass>
      </inertial>
      <self_collide>0</self_collide>
      <kinematic>0</kinematic>
      <visual name='visual'>
        <geometry>
          <cylinder>
            <radius>0.065</radius>
            <length>0.02</length>
          </cylinder>
        </geometry>
        <pose frame=''>0 0 0 0 -0 0</pose>
        <cast_shadows>1</cast_shadows>
        <transparency>0</transparency>
      </visual>
      <collision name='collision'>
        <laser_retro>0</laser_retro>
        <max_contacts>10</max_contacts>
        <pose frame=''>0 0 0 0 -0 0</pose>
        <geometry>
          <cylinder>
            <radius>0.065</radius>
            <length>0.02</length>
          </cylinder>
        </geometry>
        <surface>
          <friction>
            <ode>
              <mu>1</mu>
              <mu2>1</mu2>
              <fdir1>0 0 0</fdir1>
              <slip1>0</slip1>
              <slip2>0</slip2>
            </ode>
            <torsional>
              <coefficient>1</coefficient>
              <patch_radius>0</patch_radius>
              <surface_radius>0</surface_radius>
              <use_patch_radius>1</use_patch_radius>
              <ode>
                <slip>0</slip>
              </ode>
            </torsional>
          </friction>
          <bounce>
            <restitution_coefficient>0</restitution_coefficient>
            <threshold>1e+06</threshold>
          </bounce>
          <contact>
            <collide_without_contact>0</collide_without_contact>
            <collide_without_contact_bitmask>1</collide_without_contact_bitmask>
            <collide_bitmask>1</collide_bitmask>
            <ode>
              <soft_cfm>0</soft_cfm>
              <soft_erp>0.2</soft_erp>
              <kp>1e+13</kp>
              <kd>1</kd>
              <max_vel>0.01</max_vel>
              <min_depth>0</min_depth>
            </ode>
            <bullet>
              <split_impulse>1</split_impulse>
              <split_impulse_penetration_threshold>-0.01</split_impulse_penetration_threshold>
              <soft_cfm>0</soft_cfm>
              <soft_erp>0.2</soft_erp>
              <kp>1e+13</kp>
              <kd>1</kd>
            </bullet>
          </contact>
        </surface>
      </collision>
    </link>
    
    <link name='arm0'>
      <pose frame=''>0.1 0 .39  0.0 0.0 0.0</pose>
      <self_collide>0</self_collide>
      <kinematic>0</kinematic>
      <visual name='arm_visual'>
        <geometry>
          <cylinder>
            <radius>0.02</radius>
            <length>0.1</length>
          </cylinder>
        </geometry>
        <pose frame=''>0 0 0 0 -0 0</pose>
      </visual>
      <collision name='arm_collision'>
        <pose frame=''>0 0 0 0 -0 0</pose>
        <geometry>
          <cylinder>
            <radius>0.02</radius>
            <length>0.1</length>
          </cylinder>
        </geometry>
      </collision>
    </link>
    
     <link name='arm1'>
      <pose frame=''>0.1 0 .49  0.0 0.0 0.0</pose>
      <self_collide>0</self_collide>
      <kinematic>0</kinematic>
      <visual name='arm1_visual'>
        <geometry>
          <cylinder>
            <radius>0.02</radius>
            <length>0.1</length>
          </cylinder>
        </geometry>
        <pose frame=''>0 0 0 0 -0 0</pose>
      </visual>
      <collision name='arm1_collision'>
        <pose frame=''>0 0 0 0 -0 0</pose>
        <geometry>
          <cylinder>
            <radius>0.02</radius>
            <length>0.1</length>
          </cylinder>
        </geometry>
      </collision>
    </link>
    
     <link name='arm2'>
      <pose frame=''>0.1 0 .59  0.0 0.0 0.0</pose>
      <self_collide>0</self_collide>
      <kinematic>0</kinematic>
      <visual name='arm2_visual'>
        <geometry>
          <cylinder>
            <radius>0.02</radius>
            <length>0.1</length>
          </cylinder>
        </geometry>
        <pose frame=''>0 0 0 0 -0 0</pose>
      </visual>
      <collision name='arm2_collision'>
        <pose frame=''>0 0 0 0 -0 0</pose>
        <geometry>
          <cylinder>
            <radius>0.02</radius>
            <length>0.1</length>
          </cylinder>
        </geometry>
      </collision>
    </link>
    
    <link name='palm'>
      <pose frame=''>0.1 0 .64  0.0 1.5707963268 1.5707963268</pose>
      <self_collide>0</self_collide>
      <kinematic>0</kinematic>
      <visual name='palm_visual'>
        <geometry>
          <cylinder>
            <radius>0.02</radius>
            <length>0.1</length>
          </cylinder>
        </geometry>
        <pose frame=''>0 0 0 0 -0 0</pose>
      </visual>
      <collision name='palm_collision'>
        <pose frame=''>0 0 0 0 -0 0</pose>
        <geometry>
          <cylinder>
            <radius>0.02</radius>
            <length>0.1</length>
          </cylinder>
        </geometry>
      </collision>
    </link>
    
    <link name='right_finger'>
      <pose frame=''>0.1 -0.05 0.69  0.0 0 0.0</pose>
      <self_collide>0</self_collide>
      <kinematic>0</kinematic>
      <visual name='right_finger_visual'>
        <geometry>
          <cylinder>
            <radius>0.005</radius>
            <length>0.06</length>
          </cylinder>
        </geometry>
        <pose frame=''>0 0 0 0 -0 0</pose>
      </visual>
      <collision name='right_finger_collision'>
        <pose frame=''>0 0 0 0 -0 0</pose>
        <geometry>
          <cylinder>
            <radius>0.005</radius>
            <length>0.06</length>
          </cylinder>
        </geometry>
      </collision>
    </link>
    
    <link name='left_finger'>
      <pose frame=''>0.1 0.05 0.69  0.0 0 0.0</pose>
      <self_collide>0</self_collide>
      <kinematic>0</kinematic>
      <visual name='left_finger_visual'>
        <geometry>
          <cylinder>
            <radius>0.005</radius>
            <length>0.06</length>
          </cylinder>
        </geometry>
        <pose frame=''>0 0 0 0 -0 0</pose>
      </visual>
      <collision name='left_finger_collision'>
        <pose frame=''>0 0 0 0 -0 0</pose>
        <geometry>
          <cylinder>
            <radius>0.005</radius>
            <length>0.06</length>
          </cylinder>
        </geometry>
      </collision>
    </link>
    
    <joint name='left_finger_joint' type='prismatic'>
      <parent>palm</parent>
      <child>left_finger</child>
      <pose frame=''>0 0 0 0 -0 0</pose>
      <axis>
        <xyz>0 1 0</xyz>
        <use_parent_model_frame>1</use_parent_model_frame>
        <limit>
          <lower>-0.05</lower>
          <upper>0.0</upper>
          <effort>100</effort>
          <velocity>100</velocity>
        </limit>
      </axis>
    </joint>
    
    <joint name='right_finger_joint' type='prismatic'>
      <parent>palm</parent>
      <child>right_finger</child>
      <pose frame=''>0 0 0 0 -0 0</pose>
      <axis>
        <xyz>0 1 0</xyz>
        <use_parent_model_frame>1</use_parent_model_frame>
        <limit>
          <lower>-0</lower>
          <upper>0.05</upper>
          <effort>100</effort>
          <velocity>100</velocity>
        </limit>
      </axis>
    </joint>
    
    <joint name='palm_joint' type='revolute'>
      <parent>arm2</parent>
      <child>palm</child>
      <pose frame=''>0 0 0 0 -0 0</pose>
      <axis>
        <xyz>0 1 0</xyz>
        <use_parent_model_frame>1</use_parent_model_frame>
        <limit>
          <lower>-1.5707963268</lower>
          <upper>1.5707963268</upper>
          <effort>100</effort>
          <velocity>100</velocity>
        </limit>
      </axis>
    </joint>
    
     <joint name='arm_joint_2' type='revolute'>
      <parent>arm1</parent>
      <child>arm2</child>
      <pose frame=''>0 0 -0.03 0 -0 0</pose>
      <axis>
        <xyz>0 1 0</xyz>
        <use_parent_model_frame>1</use_parent_model_frame>
        <limit>
          <lower>0</lower>
          <upper>1.578</upper>
          <effort>100</effort>
          <velocity>100</velocity>
        </limit>
      </axis>
    </joint>
    
     <joint name='arm_joint_1' type='revolute'>
      <parent>arm0</parent>
      <child>arm1</child>
      <pose frame=''>0 0 -0.03 0 -0 0</pose>
      <axis>
        <xyz>0 1 0</xyz>
        <use_parent_model_frame>1</use_parent_model_frame>
        <limit>
          <lower>0</lower>
          <upper>1.578</upper>
          <effort>100</effort>
          <velocity>100</velocity>
        </limit>
      </axis>
    </joint>
    
    <joint name='arm_joint_0' type='revolute'>
      <parent>chassis</parent>
      <child>arm0</child>
      <pose frame=''>0 0 -0.03 0 -0 0</pose>
      <axis>
        <xyz>0 1 0</xyz>
        <use_parent_model_frame>1</use_parent_model_frame>
        <limit>
          <lower>0</lower>
          <upper>1.578</upper>
          <effort>100</effort>
          <velocity>100</velocity>
        </limit>
      </axis>
    </joint>
    
    <joint name='left_wheel_hinge' type='revolute'>
      <parent>chassis</parent>
      <child>left_wheel</child>
      <pose frame=''>0 0 -0.03 0 -0 0</pose>
      <axis>
        <xyz>0 1 0</xyz>
        <use_parent_model_frame>1</use_parent_model_frame>
        <limit>
          <lower>-1e+16</lower>
          <upper>1e+16</upper>
          <effort>-1</effort>
          <velocity>-1</velocity>
        </limit>
        <dynamics>
          <spring_reference>0</spring_reference>
          <spring_stiffness>0</spring_stiffness>
          <damping>0</damping>
          <friction>0</friction>
        </dynamics>
      </axis>
      <physics>
        <ode>
          <limit>
            <cfm>0</cfm>
            <erp>0.2</erp>
          </limit>
          <suspension>
            <cfm>0</cfm>
            <erp>0.2</erp>
          </suspension>
        </ode>
      </physics>
    </joint>
    <joint name='right_wheel_hinge' type='revolute'>
      <parent>chassis</parent>
      <child>right_wheel</child>
      <pose frame=''>0 0 0.03 0 -0 0</pose>
      <axis>
        <xyz>0 1 0</xyz>
        <use_parent_model_frame>1</use_parent_model_frame>
        <limit>
          <lower>-1e+16</lower>
          <upper>1e+16</upper>
          <effort>-1</effort>
          <velocity>-1</velocity>
        </limit>
        <dynamics>
          <spring_reference>0</spring_reference>
          <spring_stiffness>0</spring_stiffness>
          <damping>0</damping>
          <friction>0</friction>
        </dynamics>
      </axis>
      <physics>
        <ode>
          <limit>
            <cfm>0</cfm>
            <erp>0.2</erp>
          </limit>
          <suspension>
            <cfm>0</cfm>
            <erp>0.2</erp>
          </suspension>
        </ode>
      </physics>
    </joint>
    <static>0</static>
    <allow_auto_disable>1</allow_auto_disable>
    <!--
    <plugin name='differential_drive_controller' filename='libgazebo_ros_diff_drive.so'>
      <alwaysOn>true</alwaysOn>
      <updateRate>20</updateRate>
      <leftJoint>left_wheel_hinge</leftJoint>
      <rightJoint>right_wheel_hinge</rightJoint>
      <wheelSeparation>0.34</wheelSeparation>
      <wheelDiameter>0.13</wheelDiameter>
      <torque>5</torque>
      <commandTopic>cmd_vel</commandTopic>
      <odometryTopic>odom</odometryTopic>
      <odometryFrame>odom</odometryFrame>
      <robotBaseFrame>base_footprint</robotBaseFrame>
      <legacyMode>true</legacyMode>
    </plugin>
    -->
  </model>
</sdf>
